2024-09-02 10:43:11,981 - app_errors - ERROR - Uncaught exception
Traceback (most recent call last):
  File "/app/venv/bin/uvicorn", line 8, in <module>
    sys.exit(main())
             ^^^^^^
  File "/app/venv/lib/python3.11/site-packages/click/core.py", line 1157, in __call__
    return self.main(*args, **kwargs)
           ^^^^^^^^^^^^^^^^^^^^^^^^^^
  File "/app/venv/lib/python3.11/site-packages/click/core.py", line 1078, in main
    rv = self.invoke(ctx)
         ^^^^^^^^^^^^^^^^
  File "/app/venv/lib/python3.11/site-packages/click/core.py", line 1434, in invoke
    return ctx.invoke(self.callback, **ctx.params)
           ^^^^^^^^^^^^^^^^^^^^^^^^^^^^^^^^^^^^^^^
  File "/app/venv/lib/python3.11/site-packages/click/core.py", line 783, in invoke
    return __callback(*args, **kwargs)
           ^^^^^^^^^^^^^^^^^^^^^^^^^^^
  File "/app/venv/lib/python3.11/site-packages/uvicorn/main.py", line 410, in main
    run(
  File "/app/venv/lib/python3.11/site-packages/uvicorn/main.py", line 577, in run
    server.run()
  File "/app/venv/lib/python3.11/site-packages/uvicorn/server.py", line 65, in run
    return asyncio.run(self.serve(sockets=sockets))
           ^^^^^^^^^^^^^^^^^^^^^^^^^^^^^^^^^^^^^^^^
  File "/usr/local/lib/python3.11/asyncio/runners.py", line 190, in run
    return runner.run(main)
           ^^^^^^^^^^^^^^^^
  File "/usr/local/lib/python3.11/asyncio/runners.py", line 118, in run
    return self._loop.run_until_complete(task)
           ^^^^^^^^^^^^^^^^^^^^^^^^^^^^^^^^^^^
  File "/usr/local/lib/python3.11/asyncio/base_events.py", line 654, in run_until_complete
    return future.result()
           ^^^^^^^^^^^^^^^
  File "/app/venv/lib/python3.11/site-packages/uvicorn/server.py", line 69, in serve
    await self._serve(sockets)
  File "/app/venv/lib/python3.11/site-packages/uvicorn/server.py", line 76, in _serve
    config.load()
  File "/app/venv/lib/python3.11/site-packages/uvicorn/config.py", line 434, in load
    self.loaded_app = import_from_string(self.app)
                      ^^^^^^^^^^^^^^^^^^^^^^^^^^^^
  File "/app/venv/lib/python3.11/site-packages/uvicorn/importer.py", line 19, in import_from_string
    module = importlib.import_module(module_str)
             ^^^^^^^^^^^^^^^^^^^^^^^^^^^^^^^^^^^
  File "/usr/local/lib/python3.11/importlib/__init__.py", line 126, in import_module
    return _bootstrap._gcd_import(name[level:], package, level)
           ^^^^^^^^^^^^^^^^^^^^^^^^^^^^^^^^^^^^^^^^^^^^^^^^^^^^
  File "<frozen importlib._bootstrap>", line 1204, in _gcd_import
  File "<frozen importlib._bootstrap>", line 1176, in _find_and_load
  File "<frozen importlib._bootstrap>", line 1147, in _find_and_load_unlocked
  File "<frozen importlib._bootstrap>", line 690, in _load_unlocked
  File "<frozen importlib._bootstrap_external>", line 940, in exec_module
  File "<frozen importlib._bootstrap>", line 241, in _call_with_frames_removed
  File "/app/src/app.py", line 22, in <module>
    run_migrations()
  File "/app/src/database.py", line 17, in run_migrations
    command.upgrade(alembic_cfg, "head")
  File "/app/venv/lib/python3.11/site-packages/alembic/command.py", line 399, in upgrade
    script.run_env()
  File "/app/venv/lib/python3.11/site-packages/alembic/script/base.py", line 578, in run_env
    util.load_python_file(self.dir, "env.py")
  File "/app/venv/lib/python3.11/site-packages/alembic/util/pyfiles.py", line 93, in load_python_file
    module = load_module_py(module_id, path)
             ^^^^^^^^^^^^^^^^^^^^^^^^^^^^^^^
  File "/app/venv/lib/python3.11/site-packages/alembic/util/pyfiles.py", line 109, in load_module_py
    spec.loader.exec_module(module)  # type: ignore
    ^^^^^^^^^^^^^^^^^^^^^^^^^^^^^^^
  File "<frozen importlib._bootstrap_external>", line 940, in exec_module
  File "<frozen importlib._bootstrap>", line 241, in _call_with_frames_removed
  File "/app/migrations/env.py", line 6, in <module>
    from src.models import Base
ImportError: cannot import name 'Base' from 'src.models' (/app/src/models/__init__.py)
2024-09-02 10:44:34,700 - app_errors - ERROR - Uncaught exception
Traceback (most recent call last):
  File "/app/venv/bin/uvicorn", line 8, in <module>
    sys.exit(main())
             ^^^^^^
  File "/app/venv/lib/python3.11/site-packages/click/core.py", line 1157, in __call__
    return self.main(*args, **kwargs)
           ^^^^^^^^^^^^^^^^^^^^^^^^^^
  File "/app/venv/lib/python3.11/site-packages/click/core.py", line 1078, in main
    rv = self.invoke(ctx)
         ^^^^^^^^^^^^^^^^
  File "/app/venv/lib/python3.11/site-packages/click/core.py", line 1434, in invoke
    return ctx.invoke(self.callback, **ctx.params)
           ^^^^^^^^^^^^^^^^^^^^^^^^^^^^^^^^^^^^^^^
  File "/app/venv/lib/python3.11/site-packages/click/core.py", line 783, in invoke
    return __callback(*args, **kwargs)
           ^^^^^^^^^^^^^^^^^^^^^^^^^^^
  File "/app/venv/lib/python3.11/site-packages/uvicorn/main.py", line 410, in main
    run(
  File "/app/venv/lib/python3.11/site-packages/uvicorn/main.py", line 577, in run
    server.run()
  File "/app/venv/lib/python3.11/site-packages/uvicorn/server.py", line 65, in run
    return asyncio.run(self.serve(sockets=sockets))
           ^^^^^^^^^^^^^^^^^^^^^^^^^^^^^^^^^^^^^^^^
  File "/usr/local/lib/python3.11/asyncio/runners.py", line 190, in run
    return runner.run(main)
           ^^^^^^^^^^^^^^^^
  File "/usr/local/lib/python3.11/asyncio/runners.py", line 118, in run
    return self._loop.run_until_complete(task)
           ^^^^^^^^^^^^^^^^^^^^^^^^^^^^^^^^^^^
  File "/usr/local/lib/python3.11/asyncio/base_events.py", line 654, in run_until_complete
    return future.result()
           ^^^^^^^^^^^^^^^
  File "/app/venv/lib/python3.11/site-packages/uvicorn/server.py", line 69, in serve
    await self._serve(sockets)
  File "/app/venv/lib/python3.11/site-packages/uvicorn/server.py", line 76, in _serve
    config.load()
  File "/app/venv/lib/python3.11/site-packages/uvicorn/config.py", line 434, in load
    self.loaded_app = import_from_string(self.app)
                      ^^^^^^^^^^^^^^^^^^^^^^^^^^^^
  File "/app/venv/lib/python3.11/site-packages/uvicorn/importer.py", line 22, in import_from_string
    raise exc from None
  File "/app/venv/lib/python3.11/site-packages/uvicorn/importer.py", line 19, in import_from_string
    module = importlib.import_module(module_str)
             ^^^^^^^^^^^^^^^^^^^^^^^^^^^^^^^^^^^
  File "/usr/local/lib/python3.11/importlib/__init__.py", line 126, in import_module
    return _bootstrap._gcd_import(name[level:], package, level)
           ^^^^^^^^^^^^^^^^^^^^^^^^^^^^^^^^^^^^^^^^^^^^^^^^^^^^
  File "<frozen importlib._bootstrap>", line 1204, in _gcd_import
  File "<frozen importlib._bootstrap>", line 1176, in _find_and_load
  File "<frozen importlib._bootstrap>", line 1147, in _find_and_load_unlocked
  File "<frozen importlib._bootstrap>", line 690, in _load_unlocked
  File "<frozen importlib._bootstrap_external>", line 940, in exec_module
  File "<frozen importlib._bootstrap>", line 241, in _call_with_frames_removed
  File "/app/src/app.py", line 22, in <module>
    run_migrations()
  File "/app/src/database.py", line 17, in run_migrations
    command.upgrade(alembic_cfg, "head")
  File "/app/venv/lib/python3.11/site-packages/alembic/command.py", line 399, in upgrade
    script.run_env()
  File "/app/venv/lib/python3.11/site-packages/alembic/script/base.py", line 578, in run_env
    util.load_python_file(self.dir, "env.py")
  File "/app/venv/lib/python3.11/site-packages/alembic/util/pyfiles.py", line 93, in load_python_file
    module = load_module_py(module_id, path)
             ^^^^^^^^^^^^^^^^^^^^^^^^^^^^^^^
  File "/app/venv/lib/python3.11/site-packages/alembic/util/pyfiles.py", line 109, in load_module_py
    spec.loader.exec_module(module)  # type: ignore
    ^^^^^^^^^^^^^^^^^^^^^^^^^^^^^^^
  File "<frozen importlib._bootstrap_external>", line 940, in exec_module
  File "<frozen importlib._bootstrap>", line 241, in _call_with_frames_removed
  File "/app/migrations/env.py", line 6, in <module>
    from models import Base
ModuleNotFoundError: No module named 'models'
2024-09-02 10:45:35,927 - app_errors - ERROR - Uncaught exception
Traceback (most recent call last):
  File "/app/venv/bin/uvicorn", line 8, in <module>
    sys.exit(main())
             ^^^^^^
  File "/app/venv/lib/python3.11/site-packages/click/core.py", line 1157, in __call__
    return self.main(*args, **kwargs)
           ^^^^^^^^^^^^^^^^^^^^^^^^^^
  File "/app/venv/lib/python3.11/site-packages/click/core.py", line 1078, in main
    rv = self.invoke(ctx)
         ^^^^^^^^^^^^^^^^
  File "/app/venv/lib/python3.11/site-packages/click/core.py", line 1434, in invoke
    return ctx.invoke(self.callback, **ctx.params)
           ^^^^^^^^^^^^^^^^^^^^^^^^^^^^^^^^^^^^^^^
  File "/app/venv/lib/python3.11/site-packages/click/core.py", line 783, in invoke
    return __callback(*args, **kwargs)
           ^^^^^^^^^^^^^^^^^^^^^^^^^^^
  File "/app/venv/lib/python3.11/site-packages/uvicorn/main.py", line 410, in main
    run(
  File "/app/venv/lib/python3.11/site-packages/uvicorn/main.py", line 577, in run
    server.run()
  File "/app/venv/lib/python3.11/site-packages/uvicorn/server.py", line 65, in run
    return asyncio.run(self.serve(sockets=sockets))
           ^^^^^^^^^^^^^^^^^^^^^^^^^^^^^^^^^^^^^^^^
  File "/usr/local/lib/python3.11/asyncio/runners.py", line 190, in run
    return runner.run(main)
           ^^^^^^^^^^^^^^^^
  File "/usr/local/lib/python3.11/asyncio/runners.py", line 118, in run
    return self._loop.run_until_complete(task)
           ^^^^^^^^^^^^^^^^^^^^^^^^^^^^^^^^^^^
  File "/usr/local/lib/python3.11/asyncio/base_events.py", line 654, in run_until_complete
    return future.result()
           ^^^^^^^^^^^^^^^
  File "/app/venv/lib/python3.11/site-packages/uvicorn/server.py", line 69, in serve
    await self._serve(sockets)
  File "/app/venv/lib/python3.11/site-packages/uvicorn/server.py", line 76, in _serve
    config.load()
  File "/app/venv/lib/python3.11/site-packages/uvicorn/config.py", line 434, in load
    self.loaded_app = import_from_string(self.app)
                      ^^^^^^^^^^^^^^^^^^^^^^^^^^^^
  File "/app/venv/lib/python3.11/site-packages/uvicorn/importer.py", line 19, in import_from_string
    module = importlib.import_module(module_str)
             ^^^^^^^^^^^^^^^^^^^^^^^^^^^^^^^^^^^
  File "/usr/local/lib/python3.11/importlib/__init__.py", line 126, in import_module
    return _bootstrap._gcd_import(name[level:], package, level)
           ^^^^^^^^^^^^^^^^^^^^^^^^^^^^^^^^^^^^^^^^^^^^^^^^^^^^
  File "<frozen importlib._bootstrap>", line 1204, in _gcd_import
  File "<frozen importlib._bootstrap>", line 1176, in _find_and_load
  File "<frozen importlib._bootstrap>", line 1147, in _find_and_load_unlocked
  File "<frozen importlib._bootstrap>", line 690, in _load_unlocked
  File "<frozen importlib._bootstrap_external>", line 940, in exec_module
  File "<frozen importlib._bootstrap>", line 241, in _call_with_frames_removed
  File "/app/src/app.py", line 22, in <module>
    run_migrations()
  File "/app/src/database.py", line 17, in run_migrations
    command.upgrade(alembic_cfg, "head")
  File "/app/venv/lib/python3.11/site-packages/alembic/command.py", line 399, in upgrade
    script.run_env()
  File "/app/venv/lib/python3.11/site-packages/alembic/script/base.py", line 578, in run_env
    util.load_python_file(self.dir, "env.py")
  File "/app/venv/lib/python3.11/site-packages/alembic/util/pyfiles.py", line 93, in load_python_file
    module = load_module_py(module_id, path)
             ^^^^^^^^^^^^^^^^^^^^^^^^^^^^^^^
  File "/app/venv/lib/python3.11/site-packages/alembic/util/pyfiles.py", line 109, in load_module_py
    spec.loader.exec_module(module)  # type: ignore
    ^^^^^^^^^^^^^^^^^^^^^^^^^^^^^^^
  File "<frozen importlib._bootstrap_external>", line 940, in exec_module
  File "<frozen importlib._bootstrap>", line 241, in _call_with_frames_removed
  File "/app/migrations/env.py", line 6, in <module>
    from .models import Base
ImportError: attempted relative import with no known parent package
2024-09-02 10:49:14,320 - app_errors - ERROR - Uncaught exception
Traceback (most recent call last):
  File "/app/venv/bin/uvicorn", line 8, in <module>
    sys.exit(main())
             ^^^^^^
  File "/app/venv/lib/python3.11/site-packages/click/core.py", line 1157, in __call__
    return self.main(*args, **kwargs)
           ^^^^^^^^^^^^^^^^^^^^^^^^^^
  File "/app/venv/lib/python3.11/site-packages/click/core.py", line 1078, in main
    rv = self.invoke(ctx)
         ^^^^^^^^^^^^^^^^
  File "/app/venv/lib/python3.11/site-packages/click/core.py", line 1434, in invoke
    return ctx.invoke(self.callback, **ctx.params)
           ^^^^^^^^^^^^^^^^^^^^^^^^^^^^^^^^^^^^^^^
  File "/app/venv/lib/python3.11/site-packages/click/core.py", line 783, in invoke
    return __callback(*args, **kwargs)
           ^^^^^^^^^^^^^^^^^^^^^^^^^^^
  File "/app/venv/lib/python3.11/site-packages/uvicorn/main.py", line 410, in main
    run(
  File "/app/venv/lib/python3.11/site-packages/uvicorn/main.py", line 577, in run
    server.run()
  File "/app/venv/lib/python3.11/site-packages/uvicorn/server.py", line 65, in run
    return asyncio.run(self.serve(sockets=sockets))
           ^^^^^^^^^^^^^^^^^^^^^^^^^^^^^^^^^^^^^^^^
  File "/usr/local/lib/python3.11/asyncio/runners.py", line 190, in run
    return runner.run(main)
           ^^^^^^^^^^^^^^^^
  File "/usr/local/lib/python3.11/asyncio/runners.py", line 118, in run
    return self._loop.run_until_complete(task)
           ^^^^^^^^^^^^^^^^^^^^^^^^^^^^^^^^^^^
  File "/usr/local/lib/python3.11/asyncio/base_events.py", line 654, in run_until_complete
    return future.result()
           ^^^^^^^^^^^^^^^
  File "/app/venv/lib/python3.11/site-packages/uvicorn/server.py", line 69, in serve
    await self._serve(sockets)
  File "/app/venv/lib/python3.11/site-packages/uvicorn/server.py", line 76, in _serve
    config.load()
  File "/app/venv/lib/python3.11/site-packages/uvicorn/config.py", line 434, in load
    self.loaded_app = import_from_string(self.app)
                      ^^^^^^^^^^^^^^^^^^^^^^^^^^^^
  File "/app/venv/lib/python3.11/site-packages/uvicorn/importer.py", line 19, in import_from_string
    module = importlib.import_module(module_str)
             ^^^^^^^^^^^^^^^^^^^^^^^^^^^^^^^^^^^
  File "/usr/local/lib/python3.11/importlib/__init__.py", line 126, in import_module
    return _bootstrap._gcd_import(name[level:], package, level)
           ^^^^^^^^^^^^^^^^^^^^^^^^^^^^^^^^^^^^^^^^^^^^^^^^^^^^
  File "<frozen importlib._bootstrap>", line 1204, in _gcd_import
  File "<frozen importlib._bootstrap>", line 1176, in _find_and_load
  File "<frozen importlib._bootstrap>", line 1147, in _find_and_load_unlocked
  File "<frozen importlib._bootstrap>", line 690, in _load_unlocked
  File "<frozen importlib._bootstrap_external>", line 940, in exec_module
  File "<frozen importlib._bootstrap>", line 241, in _call_with_frames_removed
  File "/app/src/app.py", line 22, in <module>
    run_migrations()
  File "/app/src/database.py", line 17, in run_migrations
    command.upgrade(alembic_cfg, "head")
  File "/app/venv/lib/python3.11/site-packages/alembic/command.py", line 399, in upgrade
    script.run_env()
  File "/app/venv/lib/python3.11/site-packages/alembic/script/base.py", line 578, in run_env
    util.load_python_file(self.dir, "env.py")
  File "/app/venv/lib/python3.11/site-packages/alembic/util/pyfiles.py", line 93, in load_python_file
    module = load_module_py(module_id, path)
             ^^^^^^^^^^^^^^^^^^^^^^^^^^^^^^^
  File "/app/venv/lib/python3.11/site-packages/alembic/util/pyfiles.py", line 109, in load_module_py
    spec.loader.exec_module(module)  # type: ignore
    ^^^^^^^^^^^^^^^^^^^^^^^^^^^^^^^
  File "<frozen importlib._bootstrap_external>", line 940, in exec_module
  File "<frozen importlib._bootstrap>", line 241, in _call_with_frames_removed
  File "/app/migrations/env.py", line 6, in <module>
    from .models import Base
ImportError: attempted relative import with no known parent package
