2024-09-02 10:09:41,587 - app_errors - ERROR - An error occurred: (psycopg.errors.CannotCoerce) cannot cast type smallint to uuid
LINE 1: ...nal_id, description, received_at, data) VALUES ($1::UUID, $2...
                                                             ^
[SQL: INSERT INTO images (external_id, description, received_at, data) VALUES (%(external_id)s::UUID, %(description)s::VARCHAR, %(received_at)s::TIMESTAMP WITHOUT TIME ZONE, %(data)s) RETURNING images.id]
[parameters: {'external_id': -1, 'description': 'Не следует, однако, забывать, что новая модель организационной деятельности является качественно новой ступенью форм воздействия. Лишь интерактивные прототипы лишь добавляют фракционных разноглай', 'received_at': '2024-09-02T10:09:41.532802+00:00', 'data': Binary(b'\x89PNG\r\n\x1a\n\x00\x00\x00\rIH ... (36178 byteschars))}]
(Background on this error at: https://sqlalche.me/e/20/f405)
Traceback (most recent call last):
  File "/usr/local/lib/python3.11/site-packages/sqlalchemy/engine/base.py", line 1967, in _exec_single_context
    self.dialect.do_execute(
  File "/usr/local/lib/python3.11/site-packages/sqlalchemy/engine/default.py", line 941, in do_execute
    cursor.execute(statement, parameters)
  File "/usr/local/lib/python3.11/site-packages/psycopg/cursor.py", line 97, in execute
    raise ex.with_traceback(None)
psycopg.errors.CannotCoerce: cannot cast type smallint to uuid
LINE 1: ...nal_id, description, received_at, data) VALUES ($1::UUID, $2...
                                                             ^

The above exception was the direct cause of the following exception:

Traceback (most recent call last):
  File "/app/main.py", line 40, in <module>
    session.commit()
  File "/usr/local/lib/python3.11/site-packages/sqlalchemy/orm/session.py", line 2028, in commit
    trans.commit(_to_root=True)
  File "<string>", line 2, in commit
  File "/usr/local/lib/python3.11/site-packages/sqlalchemy/orm/state_changes.py", line 139, in _go
    ret_value = fn(self, *arg, **kw)
                ^^^^^^^^^^^^^^^^^^^^
  File "/usr/local/lib/python3.11/site-packages/sqlalchemy/orm/session.py", line 1313, in commit
    self._prepare_impl()
  File "<string>", line 2, in _prepare_impl
  File "/usr/local/lib/python3.11/site-packages/sqlalchemy/orm/state_changes.py", line 139, in _go
    ret_value = fn(self, *arg, **kw)
                ^^^^^^^^^^^^^^^^^^^^
  File "/usr/local/lib/python3.11/site-packages/sqlalchemy/orm/session.py", line 1288, in _prepare_impl
    self.session.flush()
  File "/usr/local/lib/python3.11/site-packages/sqlalchemy/orm/session.py", line 4352, in flush
    self._flush(objects)
  File "/usr/local/lib/python3.11/site-packages/sqlalchemy/orm/session.py", line 4487, in _flush
    with util.safe_reraise():
  File "/usr/local/lib/python3.11/site-packages/sqlalchemy/util/langhelpers.py", line 146, in __exit__
    raise exc_value.with_traceback(exc_tb)
  File "/usr/local/lib/python3.11/site-packages/sqlalchemy/orm/session.py", line 4448, in _flush
    flush_context.execute()
  File "/usr/local/lib/python3.11/site-packages/sqlalchemy/orm/unitofwork.py", line 466, in execute
    rec.execute(self)
  File "/usr/local/lib/python3.11/site-packages/sqlalchemy/orm/unitofwork.py", line 642, in execute
    util.preloaded.orm_persistence.save_obj(
  File "/usr/local/lib/python3.11/site-packages/sqlalchemy/orm/persistence.py", line 93, in save_obj
    _emit_insert_statements(
  File "/usr/local/lib/python3.11/site-packages/sqlalchemy/orm/persistence.py", line 1233, in _emit_insert_statements
    result = connection.execute(
             ^^^^^^^^^^^^^^^^^^^
  File "/usr/local/lib/python3.11/site-packages/sqlalchemy/engine/base.py", line 1418, in execute
    return meth(
           ^^^^^
  File "/usr/local/lib/python3.11/site-packages/sqlalchemy/sql/elements.py", line 515, in _execute_on_connection
    return connection._execute_clauseelement(
           ^^^^^^^^^^^^^^^^^^^^^^^^^^^^^^^^^^
  File "/usr/local/lib/python3.11/site-packages/sqlalchemy/engine/base.py", line 1640, in _execute_clauseelement
    ret = self._execute_context(
          ^^^^^^^^^^^^^^^^^^^^^^
  File "/usr/local/lib/python3.11/site-packages/sqlalchemy/engine/base.py", line 1846, in _execute_context
    return self._exec_single_context(
           ^^^^^^^^^^^^^^^^^^^^^^^^^^
  File "/usr/local/lib/python3.11/site-packages/sqlalchemy/engine/base.py", line 1986, in _exec_single_context
    self._handle_dbapi_exception(
  File "/usr/local/lib/python3.11/site-packages/sqlalchemy/engine/base.py", line 2355, in _handle_dbapi_exception
    raise sqlalchemy_exception.with_traceback(exc_info[2]) from e
  File "/usr/local/lib/python3.11/site-packages/sqlalchemy/engine/base.py", line 1967, in _exec_single_context
    self.dialect.do_execute(
  File "/usr/local/lib/python3.11/site-packages/sqlalchemy/engine/default.py", line 941, in do_execute
    cursor.execute(statement, parameters)
  File "/usr/local/lib/python3.11/site-packages/psycopg/cursor.py", line 97, in execute
    raise ex.with_traceback(None)
sqlalchemy.exc.ProgrammingError: (psycopg.errors.CannotCoerce) cannot cast type smallint to uuid
LINE 1: ...nal_id, description, received_at, data) VALUES ($1::UUID, $2...
                                                             ^
[SQL: INSERT INTO images (external_id, description, received_at, data) VALUES (%(external_id)s::UUID, %(description)s::VARCHAR, %(received_at)s::TIMESTAMP WITHOUT TIME ZONE, %(data)s) RETURNING images.id]
[parameters: {'external_id': -1, 'description': 'Не следует, однако, забывать, что новая модель организационной деятельности является качественно новой ступенью форм воздействия. Лишь интерактивные прототипы лишь добавляют фракционных разноглай', 'received_at': '2024-09-02T10:09:41.532802+00:00', 'data': Binary(b'\x89PNG\r\n\x1a\n\x00\x00\x00\rIH ... (36178 byteschars))}]
(Background on this error at: https://sqlalche.me/e/20/f405)
2024-09-02 10:09:41,596 - app_errors - ERROR - An exception occurred
Traceback (most recent call last):
  File "/usr/local/lib/python3.11/site-packages/sqlalchemy/engine/base.py", line 1967, in _exec_single_context
    self.dialect.do_execute(
  File "/usr/local/lib/python3.11/site-packages/sqlalchemy/engine/default.py", line 941, in do_execute
    cursor.execute(statement, parameters)
  File "/usr/local/lib/python3.11/site-packages/psycopg/cursor.py", line 97, in execute
    raise ex.with_traceback(None)
psycopg.errors.CannotCoerce: cannot cast type smallint to uuid
LINE 1: ...nal_id, description, received_at, data) VALUES ($1::UUID, $2...
                                                             ^

The above exception was the direct cause of the following exception:

Traceback (most recent call last):
  File "/app/main.py", line 40, in <module>
    session.commit()
  File "/usr/local/lib/python3.11/site-packages/sqlalchemy/orm/session.py", line 2028, in commit
    trans.commit(_to_root=True)
  File "<string>", line 2, in commit
  File "/usr/local/lib/python3.11/site-packages/sqlalchemy/orm/state_changes.py", line 139, in _go
    ret_value = fn(self, *arg, **kw)
                ^^^^^^^^^^^^^^^^^^^^
  File "/usr/local/lib/python3.11/site-packages/sqlalchemy/orm/session.py", line 1313, in commit
    self._prepare_impl()
  File "<string>", line 2, in _prepare_impl
  File "/usr/local/lib/python3.11/site-packages/sqlalchemy/orm/state_changes.py", line 139, in _go
    ret_value = fn(self, *arg, **kw)
                ^^^^^^^^^^^^^^^^^^^^
  File "/usr/local/lib/python3.11/site-packages/sqlalchemy/orm/session.py", line 1288, in _prepare_impl
    self.session.flush()
  File "/usr/local/lib/python3.11/site-packages/sqlalchemy/orm/session.py", line 4352, in flush
    self._flush(objects)
  File "/usr/local/lib/python3.11/site-packages/sqlalchemy/orm/session.py", line 4487, in _flush
    with util.safe_reraise():
  File "/usr/local/lib/python3.11/site-packages/sqlalchemy/util/langhelpers.py", line 146, in __exit__
    raise exc_value.with_traceback(exc_tb)
  File "/usr/local/lib/python3.11/site-packages/sqlalchemy/orm/session.py", line 4448, in _flush
    flush_context.execute()
  File "/usr/local/lib/python3.11/site-packages/sqlalchemy/orm/unitofwork.py", line 466, in execute
    rec.execute(self)
  File "/usr/local/lib/python3.11/site-packages/sqlalchemy/orm/unitofwork.py", line 642, in execute
    util.preloaded.orm_persistence.save_obj(
  File "/usr/local/lib/python3.11/site-packages/sqlalchemy/orm/persistence.py", line 93, in save_obj
    _emit_insert_statements(
  File "/usr/local/lib/python3.11/site-packages/sqlalchemy/orm/persistence.py", line 1233, in _emit_insert_statements
    result = connection.execute(
             ^^^^^^^^^^^^^^^^^^^
  File "/usr/local/lib/python3.11/site-packages/sqlalchemy/engine/base.py", line 1418, in execute
    return meth(
           ^^^^^
  File "/usr/local/lib/python3.11/site-packages/sqlalchemy/sql/elements.py", line 515, in _execute_on_connection
    return connection._execute_clauseelement(
           ^^^^^^^^^^^^^^^^^^^^^^^^^^^^^^^^^^
  File "/usr/local/lib/python3.11/site-packages/sqlalchemy/engine/base.py", line 1640, in _execute_clauseelement
    ret = self._execute_context(
          ^^^^^^^^^^^^^^^^^^^^^^
  File "/usr/local/lib/python3.11/site-packages/sqlalchemy/engine/base.py", line 1846, in _execute_context
    return self._exec_single_context(
           ^^^^^^^^^^^^^^^^^^^^^^^^^^
  File "/usr/local/lib/python3.11/site-packages/sqlalchemy/engine/base.py", line 1986, in _exec_single_context
    self._handle_dbapi_exception(
  File "/usr/local/lib/python3.11/site-packages/sqlalchemy/engine/base.py", line 2355, in _handle_dbapi_exception
    raise sqlalchemy_exception.with_traceback(exc_info[2]) from e
  File "/usr/local/lib/python3.11/site-packages/sqlalchemy/engine/base.py", line 1967, in _exec_single_context
    self.dialect.do_execute(
  File "/usr/local/lib/python3.11/site-packages/sqlalchemy/engine/default.py", line 941, in do_execute
    cursor.execute(statement, parameters)
  File "/usr/local/lib/python3.11/site-packages/psycopg/cursor.py", line 97, in execute
    raise ex.with_traceback(None)
sqlalchemy.exc.ProgrammingError: (psycopg.errors.CannotCoerce) cannot cast type smallint to uuid
LINE 1: ...nal_id, description, received_at, data) VALUES ($1::UUID, $2...
                                                             ^
[SQL: INSERT INTO images (external_id, description, received_at, data) VALUES (%(external_id)s::UUID, %(description)s::VARCHAR, %(received_at)s::TIMESTAMP WITHOUT TIME ZONE, %(data)s) RETURNING images.id]
[parameters: {'external_id': -1, 'description': 'Не следует, однако, забывать, что новая модель организационной деятельности является качественно новой ступенью форм воздействия. Лишь интерактивные прототипы лишь добавляют фракционных разноглай', 'received_at': '2024-09-02T10:09:41.532802+00:00', 'data': Binary(b'\x89PNG\r\n\x1a\n\x00\x00\x00\rIH ... (36178 byteschars))}]
(Background on this error at: https://sqlalche.me/e/20/f405)
